<?xml version="1.0" encoding="utf-8"?>
<robot xmlns:xacro="http://www.ros.org/wiki/xacro" name="hand">
  <xacro:macro name="hand" params="connected_to:='' ns:='' rpy:='0 0 0' xyz:='0 0 0' ">
	
	<xacro:property name="camera_link" value="0.03" /> <!-- Size of square 'camera' box -->
	<xacro:property name="ft_link" value="0.01" /> <!-- Size of square 'force_torque' box -->

    <xacro:unless value="${connected_to == ''}">
      <joint name="${ns}_hand_joint" type="fixed">
        <parent link="${connected_to}"/>
        <child link="${ns}_hand"/>
        <origin xyz="${xyz}" rpy="${rpy}"/>
      </joint>
    </xacro:unless>

    <xacro:arg name="gazebo" default="true"/>
    <xacro:if value="$(arg gazebo)">
      <!-- Gazebo Tags -->
      <xacro:include filename="$(find franka_gazebo)/robots/hand.gazebo.xacro"/>
    </xacro:if>

    <link name="${ns}_hand">
      <inertial>
        <mass value="0.73" />
        <origin xyz="0 0.0015244 0.0275912" rpy="0 0 0" />
        <inertia ixx="0.00278560230025" ixy="0.0" ixz="0.0" iyy="0.000400033405336" iyz="0.0" izz="0.00256378041832" />
      </inertial>
      <visual>
        <origin xyz="${xyz}" rpy="0 0 0"/>
        <geometry>
          <mesh filename="package://franka_gazebo/meshes/visual/hand.dae"/>
        </geometry>
        <material name="">
          <color rgba="1 1 1 1"/>
        </material>
      </visual>
      <collision>
        <origin xyz="${xyz}" rpy="0 0 0"/>
        <geometry>
          <mesh filename="package://franka_gazebo/meshes/collision/hand.stl"/>
        </geometry>
      </collision>
    </link>

		<!-- Camera -->
		<link name="${ns}_camera_link">
			<collision>
			  <origin xyz="0 0 0" rpy="0 0 0"/>
			  <geometry>
			<box size="${camera_link} ${camera_link} ${camera_link}"/>
			  </geometry>
			</collision>

			<visual>
			  <origin xyz="0 0 0" rpy="0 0 0"/>
			  <geometry>
			<box size="${camera_link} ${camera_link} ${camera_link}"/>
			  </geometry>
			</visual>

			<inertial>
			  <mass value="1e-5" />
			  <origin xyz="0 0 0" rpy="0 0 0"/>
			  <inertia ixx="1e-6" ixy="0" ixz="0" iyy="1e-6" iyz="0" izz="1e-6" />
			</inertial>
		</link>

		<joint name="${ns}_camera_joint" type="fixed">
			<axis xyz="0 0 0" />
			<origin xyz="0.04 0 0.05" rpy="${pi} ${-pi/2} 0"/>
			<parent link="${ns}_hand"/>
			<child link="${ns}_camera_link"/>
		</joint>

		<joint name="camera_optical_joint" type="fixed">
			<!-- these values have to be these values otherwise the gazebo camera
			    image won't be aligned properly with the frame it is supposedly
			    originating from -->
			<origin xyz="0 0 0" rpy="${-pi/2} 0 ${-pi/2}"/>
			<parent link="${ns}_camera_link"/>
			<child link="${ns}_camera_link_optical"/>
		</joint>

		<link name="${ns}_camera_link_optical">
		</link>

    <link name="${ns}_leftfinger">
      <inertial>
        <mass value="0.1" />
        <origin xyz="0 0.0145644 0.0227941" rpy="0 0 0" />
        <inertia ixx="3.01220925051e-05" ixy="0.0" ixz="0.0" iyy="2.95873808038e-05" iyz="0.0" izz="6.95125211657e-06" />
      </inertial>
      <visual>
        <origin xyz="${xyz}" rpy="0 0 0"/>
        <geometry>
          <mesh filename="package://franka_gazebo/meshes/visual/finger.dae"/>
        </geometry>
        <material name="">
          <color rgba="1 1 1 1"/>
        </material>
      </visual>
      <collision>
        <origin xyz="${xyz}" rpy="0 0 0"/>
        <geometry>
          <mesh filename="package://franka_gazebo/meshes/collision/finger.stl"/>
        </geometry>
      </collision>
    </link>

    <link name="${ns}_rightfinger">
      <inertial>
        <mass value="0.1" />
        <origin xyz="0 0.0145644 0.0227941" rpy="0 0 ${pi}" />
        <inertia ixx="3.01220925051e-05" ixy="0.0" ixz="0.0" iyy="2.95873808038e-05" iyz="0.0" izz="6.95125211657e-06" />
      </inertial>
      <visual>
        <origin xyz="0 0 0" rpy="0 0 ${pi}"/>
        <geometry>
          <mesh filename="package://franka_gazebo/meshes/visual/finger.dae"/>
        </geometry>
        <material name="">
          <color rgba="1 1 1 1"/>
        </material>
      </visual>
      <collision>
        <origin xyz="0 0 0" rpy="0 0 ${pi}"/>
        <geometry>
          <mesh filename="package://franka_gazebo/meshes/collision/finger.stl"/>
        </geometry>
      </collision>
    </link>

    <joint name="${ns}_finger_joint1" type="prismatic">
      <parent link="${ns}_hand"/>
      <child link="${ns}_leftfinger"/>
      <origin xyz="0 0 0.0584" rpy="0 0 0"/>
      <axis xyz="0 1 0"/>
      <limit effort="20" lower="-0.001" upper="0.04" velocity="0.3"/>
    </joint>

    <joint name="${ns}_finger_joint2" type="prismatic">
      <parent link="${ns}_hand"/>
      <child link="${ns}_rightfinger"/>
      <origin xyz="0 0 0.0584" rpy="0 0 0"/>
      <axis xyz="0 -1 0"/>
      <limit effort="20" lower="-0.001" upper="0.04" velocity="0.3"/>
    </joint>

		<link name="${ns}_ft_leftfinger">
			<collision>
			  <origin xyz="0 0 0" rpy="0 0 0"/>
			  <geometry>
			<box size="${ft_link} ${ft_link} ${ft_link}"/>
			  </geometry>
			</collision>

			<visual>
			  <origin xyz="0 0 0" rpy="0 0 0"/>
			  <geometry>
			<box size="${ft_link} ${ft_link} ${ft_link}"/>
			  </geometry>
			</visual>

			<inertial>
			  <mass value="1e-5" />
			  <origin xyz="0 0 0" rpy="0 0 0"/>
			  <inertia ixx="1e-6" ixy="0" ixz="0" iyy="1e-6" iyz="0" izz="1e-6" />
			</inertial>
		</link>

		<link name="${ns}_ft_rightfinger">
			<collision>
			  <origin xyz="0 0 0" rpy="0 0 0"/>
			  <geometry>
			<box size="${ft_link} ${ft_link} ${ft_link}"/>
			  </geometry>
			</collision>

			<visual>
			  <origin xyz="0 0 0" rpy="0 0 0"/>
			  <geometry>
			<box size="${ft_link} ${ft_link} ${ft_link}"/>
			  </geometry>
			</visual>

			<inertial>
			  <mass value="1e-5" />
			  <origin xyz="0 0 0" rpy="0 0 0"/>
			  <inertia ixx="1e-6" ixy="0" ixz="0" iyy="1e-6" iyz="0" izz="1e-6" />
			</inertial>
		</link>

		<joint name="${ns}_ft_joint_1" type="revolute">
		    <parent link="${ns}_leftfinger"/>
		    <child link="${ns}_ft_leftfinger"/>
		    <origin xyz="0 -0.005 0.06" rpy="0 0 0"/>
				<limit velocity="6.5" effort="1000" lower="0" upper="0" />
		  </joint>

    <joint name="${ns}_ft_joint_2" type="revolute">
      <parent link="${ns}_rightfinger"/>
      <child link="${ns}_ft_rightfinger"/>
      <origin xyz="0 0.005 0.06" rpy="0 0 ${pi}"/>
			<limit velocity="6.5" effort="1000" lower="0" upper="0" />
    </joint>

  </xacro:macro>
</robot>
